<!--URDF generated by ONSHAPE BY PTC INC, 1.213-->
<robot name="pentos">
    <link name="a_axis">
        <inertial>
            <mass value="4.53743e-05" />
            <origin xyz="0.1 1.09746e-17 -0.0470433" rpy="0 -0 0" />
            <inertia ixx="8.66666e-09" ixy="0" ixz="0" iyy="1.89324e-07" iyz="0" izz="1.92057e-07" />
        </inertial>
        <visual>
            <origin xyz="0.1 3.46945e-18 -0.052" rpy="0 -0 0" />
            <geometry>
                <mesh filename="package://pentos/meshes/A Axis.gltf" scale="1 1 1" />
            </geometry>
            <material name="0.615686_0.811765_0.929412_0.000000_0.000000">
                <texture />
                <color rgba="0.615686 0.811765 0.929412 1" />
            </material>
        </visual>
        <collision>
            <origin xyz="0.1 3.46945e-18 -0.052" rpy="0 -0 0" />
            <geometry>
                <mesh filename="package://pentos/meshes/A Axis.gltf" scale="1 1 1" />
            </geometry>
        </collision>
    </link>
    <link name="b_axis">
        <inertial>
            <mass value="0.0004374" />
            <origin xyz="-1.15648e-18 6.95496e-18 0.027" rpy="0 -0 0" />
            <inertia ixx="4.01533e-07" ixy="0" ixz="0" iyy="4.01533e-07" iyz="0" izz="5.9049e-07" />
        </inertial>
        <visual>
            <origin xyz="-1.15648e-18 6.8104e-18 0" rpy="0 -0 0" />
            <geometry>
                <mesh filename="package://pentos/meshes/B Axis.gltf" scale="1 1 1" />
            </geometry>
            <material name="0.615686_0.811765_0.929412_0.000000_0.000000">
                <texture />
                <color rgba="0.615686 0.811765 0.929412 1" />
            </material>
        </visual>
        <collision>
            <origin xyz="-1.15648e-18 6.8104e-18 0" rpy="0 -0 0" />
            <geometry>
                <mesh filename="package://pentos/meshes/B Axis.gltf" scale="1 1 1" />
            </geometry>
        </collision>
    </link>
    <link name="frame">
        <inertial>
            <mass value="0.006852" />
            <origin xyz="-7.91157e-18 -4.05621e-18 0.109574" rpy="0 -0 0" />
            <inertia ixx="0.000217618" ixy="0" ixz="0" iyy="0.000246301" iyz="0" izz="0.000119693" />
        </inertial>
        <visual>
            <origin xyz="0 0 0" rpy="0 -0 0" />
            <geometry>
                <mesh filename="package://pentos/meshes/Frame.gltf" scale="1 1 1" />
            </geometry>
            <material name="0.615686_0.811765_0.929412_0.000000_0.000000">
                <texture />
                <color rgba="0.615686 0.811765 0.929412 1" />
            </material>
        </visual>
        <collision>
            <origin xyz="0 0 0" rpy="0 -0 0" />
            <geometry>
                <mesh filename="package://pentos/meshes/Frame.gltf" scale="1 1 1" />
            </geometry>
        </collision>
    </link>
    <link name="root" />
    <link name="x_carriage">
        <inertial>
            <mass value="4.00212e-05" />
            <origin xyz="-0.02 -0.025 -0.020014" rpy="0 -0 0" />
            <inertia ixx="3.36816e-08" ixy="0" ixz="0" iyy="1.96816e-08" iyz="0" izz="2.46667e-08" />
        </inertial>
        <visual>
            <origin xyz="-0.04 -0.025 -0.02" rpy="0 -0 0" />
            <geometry>
                <mesh filename="package://pentos/meshes/X Carriage.gltf" scale="1 1 1" />
            </geometry>
            <material name="0.615686_0.811765_0.929412_0.000000_0.000000">
                <texture />
                <color rgba="0.615686 0.811765 0.929412 1" />
            </material>
        </visual>
        <collision>
            <origin xyz="-0.04 -0.025 -0.02" rpy="0 -0 0" />
            <geometry>
                <mesh filename="package://pentos/meshes/X Carriage.gltf" scale="1 1 1" />
            </geometry>
        </collision>
    </link>
    <link name="x_gantry">
        <inertial>
            <mass value="0.000552" />
            <origin xyz="0.165 -0.02 0" rpy="0 -0 0" />
            <inertia ixx="1.982e-07" ixy="0" ixz="0" iyy="3.916e-06" iyz="0" izz="3.967e-06" />
        </inertial>
        <visual>
            <origin xyz="0.165 -0.02 -0.02" rpy="0 -0 0" />
            <geometry>
                <mesh filename="package://pentos/meshes/X Gantry.gltf" scale="1 1 1" />
            </geometry>
            <material name="0.615686_0.811765_0.929412_0.000000_0.000000">
                <texture />
                <color rgba="0.615686 0.811765 0.929412 1" />
            </material>
        </visual>
        <collision>
            <origin xyz="0.165 -0.02 -0.02" rpy="0 -0 0" />
            <geometry>
                <mesh filename="package://pentos/meshes/X Gantry.gltf" scale="1 1 1" />
            </geometry>
        </collision>
    </link>
    <link name="y_gantry">
        <inertial>
            <mass value="0.000213399" />
            <origin xyz="-0.02 3.46945e-18 0.00596838" rpy="0 -0 0" />
            <inertia ixx="9.61878e-07" ixy="0" ixz="0" iyy="6.56358e-07" iyz="0" izz="1.52845e-06" />
        </inertial>
        <visual>
            <origin xyz="-0.02 3.46945e-18 0" rpy="0 -0 0" />
            <geometry>
                <mesh filename="package://pentos/meshes/Y Gantry.gltf" scale="1 1 1" />
            </geometry>
            <material name="0.615686_0.811765_0.929412_0.000000_0.000000">
                <texture />
                <color rgba="0.615686 0.811765 0.929412 1" />
            </material>
        </visual>
        <collision>
            <origin xyz="-0.02 3.46945e-18 0" rpy="0 -0 0" />
            <geometry>
                <mesh filename="package://pentos/meshes/Y Gantry.gltf" scale="1 1 1" />
            </geometry>
        </collision>
    </link>
    <joint name="a_axis_0" type="continuous">
        <origin xyz="-0.02 0.1 0.082" rpy="3.46945e-16 -4.66567e-16 -1.5708" />
        <axis xyz="-1 0 0" />
        <parent link="y_gantry" />
        <child link="a_axis" />
    </joint>
    <joint name="b_axis_0" type="continuous">
        <origin xyz="0.1 -1.4456e-17 -0.047" rpy="-2.72712e-31 6.93889e-18 1.5708" />
        <axis xyz="0 0 -1" />
        <parent link="a_axis" />
        <child link="b_axis" />
    </joint>
    <joint name="fixed_node_to_root_joint_0" type="fixed">
        <origin xyz="0 0 0" rpy="0 -0 0" />
        <axis xyz="0 0 1" />
        <parent link="root" />
        <child link="frame" />
    </joint>
    <joint name="x_axis_0" type="prismatic">
        <origin xyz="0.165 0.005 0.02" rpy="0 -0 3.42114e-49" />
        <axis xyz="-1 0 0" />
        <parent link="x_gantry" />
        <child link="x_carriage" />
        <limit effort="1" velocity="1" lower="-10000" upper="10000" />
    </joint>
    <joint name="y_axis_0" type="prismatic">
        <origin xyz="0.02 0.17 0.08" rpy="0 -0 1.98254e-16" />
        <axis xyz="3.46945e-16 1 0" />
        <parent link="frame" />
        <child link="y_gantry" />
        <limit effort="1" velocity="1" lower="-10000" upper="10000" />
    </joint>
    <joint name="z_axis_0" type="prismatic">
        <origin xyz="-0.165 0.02 0.203" rpy="-6.50521e-17 5.78241e-17 -3.76158e-33" />
        <axis xyz="0 0 -1" />
        <parent link="frame" />
        <child link="x_gantry" />
        <limit effort="1" velocity="1" lower="-10000" upper="10000" />
    </joint>
    <ros2_control name="GazeboSimSystem" type="system">
        <hardware>
            <plugin>gz_ros2_control/GazeboSimSystem</plugin>
        </hardware>
        <joint name="x_axis_0">
            <command_interface name="position" />
            <state_interface name="position" />
            <state_interface name="velocity" />
        </joint>
        <joint name="y_axis_0">
            <command_interface name="position" />
            <state_interface name="position" />
            <state_interface name="velocity" />
        </joint>
        <joint name="z_axis_0">
            <command_interface name="position" />
            <state_interface name="position" />
            <state_interface name="velocity" />
        </joint>
        <joint name="a_axis_0">
            <command_interface name="position" />
            <state_interface name="position" />
            <state_interface name="velocity" />
        </joint>
        <joint name="b_axis_0">
            <command_interface name="position" />
            <state_interface name="position" />
            <state_interface name="velocity" />
        </joint>
    </ros2_control>
    <gazebo>
        <plugin filename="libgz_ros2_control-system.so" name="gz_ros2_control::GazeboSimROS2ControlPlugin">
            <parameters>$(find pentos)/config/pentos_controllers.yaml</parameters>
        </plugin>
    </gazebo>
    <gazebo reference="a_axis">
        <self_collide>true</self_collide>
    </gazebo>
    <gazebo reference="b_axis">
        <self_collide>true</self_collide>
    </gazebo>
    <gazebo reference="frame">
        <self_collide>true</self_collide>
    </gazebo>
    <gazebo reference="x_carriage">
        <self_collide>true</self_collide>
    </gazebo>
    <gazebo reference="x_gantry">
        <self_collide>true</self_collide>
    </gazebo>
    <gazebo reference="y_gantry">
        <self_collide>true</self_collide>
    </gazebo>
</robot>
